<?xml version="1.0" ?>
<!-- =================================================================================== -->
<!-- |    This document was autogenerated by xacro from xarm_device.urdf.xacro         | -->
<!-- |    EDITING THIS FILE BY HAND IS NOT RECOMMENDED                                 | -->
<!-- =================================================================================== -->
<robot name="xarm7_softgripper">
  <!-- Insert at the beginning of xarm_device_macro.xacro -->
  <material name="Black">
    <color rgba="0.0 0.0 0.0 1.0"/>
  </material>
  <material name="Red">
    <color rgba="0.8 0.0 0.0 1.0"/>
  </material>
  <material name="White">
    <color rgba="1.0 1.0 1.0 1.0"/>
  </material>
  <material name="Silver">
    <color rgba="0.753 0.753 0.753 1.0"/>
  </material>

  <!-- <link name="world"/> -->
  
  <link name="link_eef">
    <!-- <visual>
      <geometry>
        <mesh filename="xarm_description/meshes/camera/realsense/visual/d435_with_tilt_cam_stand.glb"/>
      </geometry>
      <origin rpy="0 0 3.141592653589793" xyz="0 0 0"/>
    </visual> -->
    <collision>
      <geometry>
        <mesh filename="xarm_description/meshes/camera/realsense/collision/d435_with_tilt_cam_stand.STL"/>
      </geometry>
      <origin rpy="0 0 3.141592653589793" xyz="0 0 0"/>
    </collision>
  </link>
  <link name="camera_link"/>
  <link name="camera_depth_frame"/>
  <link name="camera_depth_optical_frame"/>
  <link name="camera_color_frame"/>
  <link name="camera_color_optical_frame"/>
  <link name="camera_left_ir_frame"/>
  <link name="camera_left_ir_optical_frame"/>
  <link name="camera_right_ir_frame"/>
  <link name="camera_right_ir_optical_frame"/>
  <!-- Compute origin xyz
    x, z = 0.06746, 0.0237
    r = np.sqrt(x**2 + z**2)
    dx, dz = 0.0014, -0.0112  # from blender model
    theta = np.arctan2(z, x)
    new_x = r * np.cos(theta + np.deg2rad(15)) + dx
    new_z = r * np.sin(theta + np.deg2rad(15)) + dz
  -->
  <joint name="camera_link_joint" type="fixed">
    <parent link="link_eef"/>
    <child link="camera_link"/>
    <origin rpy="3.141592653589793 -1.832595714594046 3.141592653589793" xyz="-0.06042734 0.0175 0.02915237"/>
  </joint>
  <joint name="camera_depth_joint" type="fixed">
    <parent link="camera_link"/>
    <child link="camera_depth_frame"/>
    <origin rpy="0 0 0" xyz="0 0 0"/>
  </joint>
  <joint name="camera_depth_optical_joint" type="fixed">
    <parent link="camera_depth_frame"/>
    <child link="camera_depth_optical_frame"/>
    <origin rpy="-1.5707963267948966 0 -1.5707963267948966" xyz="0 0 0"/>
  </joint>
  <joint name="camera_color_joint" type="fixed">
    <parent link="camera_link"/>
    <child link="camera_color_frame"/>
    <origin rpy="0 0 0" xyz="0 0.015 0"/>
  </joint>
  <joint name="camera_color_optical_joint" type="fixed">
    <parent link="camera_color_frame"/>
    <child link="camera_color_optical_frame"/>
    <origin rpy="-1.5707963267948966 0 -1.5707963267948966" xyz="0 0 0"/>
  </joint>
  <joint name="camera_left_ir_joint" type="fixed">
    <parent link="camera_link"/>
    <child link="camera_left_ir_frame"/>
    <origin rpy="0 0 0" xyz="0 0 0"/>
  </joint>
  <joint name="camera_left_ir_optical_joint" type="fixed">
    <parent link="camera_left_ir_frame"/>
    <child link="camera_left_ir_optical_frame"/>
    <origin rpy="-1.5707963267948966 0 -1.5707963267948966" xyz="0 0 0"/>
  </joint>
  <joint name="camera_right_ir_joint" type="fixed">
    <parent link="camera_link"/>
    <child link="camera_right_ir_frame"/>
    <origin rpy="0 0 0" xyz="0 -0.050 0"/>
  </joint>
  <joint name="camera_right_ir_optical_joint" type="fixed">
    <parent link="camera_right_ir_frame"/>
    <child link="camera_right_ir_optical_frame"/>
    <origin rpy="-1.5707963267948966 0 -1.5707963267948966" xyz="0 0 0"/>
  </joint>
  <!-- <joint name="joint_eef" type="fixed">
    <origin rpy="0 0 0" xyz="0 0 0"/>
    <child link="link_eef"/>
  </joint> -->
  <joint name="gripper_fix" type="fixed">
    <parent link="link_eef"/>
    <child link="xarm_gripper_base_link"/>
    <origin rpy="0 0 0" xyz="0 0 0.005"/>
  </joint>
  <link name="xarm_gripper_base_link">
    <inertial>
      <origin rpy="0 0 0" xyz="-0.00065489 -0.0018497 0.048028"/>
      <mass value="0.54156"/>
      <inertia ixx="0.00047106" ixy="3.9292E-07" ixz="2.6537E-06" iyy="0.00033072" iyz="-1.0975E-05" izz="0.00025642"/>
    </inertial>
    <visual>
      <geometry>
        <mesh filename="xarm_description/meshes/gripper/xarm/base_link.STL"/>
      </geometry>
      <origin rpy="0 0 0" xyz="0 0 0"/>
      <!-- <material name="White"/> -->
    </visual>
    <collision>
      <geometry>
        <mesh filename="xarm_description/meshes/gripper/xarm/base_link_collision.STL"/>
      </geometry>
      <origin rpy="0 0 0" xyz="0 0 0"/>
    </collision>
  </link>
  <link name="left_outer_knuckle">
    <inertial>
      <origin rpy="0 0 0" xyz="2.9948E-14 0.021559 0.015181"/>
      <mass value="0.033618"/>
      <inertia ixx="1.9111E-05" ixy="-1.8803E-17" ixz="-1.1002E-17" iyy="6.6256E-06" iyz="-7.3008E-06" izz="1.3185E-05"/>
    </inertial>
    <visual>
      <geometry>
        <mesh filename="xarm_description/meshes/gripper/xarm/left_outer_knuckle_black.glb"/>
      </geometry>
      <origin rpy="0 0 0" xyz="0 0 0"/>
      <!-- <material name="Silver"/> -->
    </visual>
    <collision>
      <geometry>
        <mesh filename="xarm_description/meshes/gripper/xarm/left_outer_knuckle_black.glb"/>
      </geometry>
      <origin rpy="0 0 0" xyz="0 0 0"/>
    </collision>
  </link>
  <joint name="drive_joint" type="revolute">
    <origin rpy="0.85 0 0" xyz="0 0.035 0.059098"/>
    <parent link="xarm_gripper_base_link"/>
    <child link="left_outer_knuckle"/>
    <axis xyz="-1 0 0"/>
    <limit effort="50" lower="0" upper="0.85" velocity="2"/>
  </joint>
  <link name="left_finger">
    <inertial>
      <origin rpy="0 0 0" xyz="-2.4536E-14 -0.016413 0.029258"/>
      <mass value="0.048304"/>
      <inertia ixx="1.7493E-05" ixy="-4.2156E-19" ixz="6.9164E-18" iyy="1.7225E-05" iyz="4.6433E-06" izz="5.1466E-06"/>
    </inertial>
    <visual>
      <geometry>
        <mesh filename="xarm_description/meshes/soft_gripper/left_finger.obj"/>
      </geometry>
      <origin rpy="0 0 0" xyz="0 0 0"/>
      <!-- <material name="Silver"/> -->
    </visual>
    <collision>
      <geometry>
        <mesh filename="xarm_description/meshes/soft_gripper/left_finger.obj"/>
      </geometry>
      <origin rpy="0 0 0" xyz="0 0 0"/>
    </collision>
  </link>
  <joint name="left_finger_joint" type="revolute">
    <origin rpy="-0.85 0 0" xyz="0 0.035465 0.042039"/>
    <parent link="left_outer_knuckle"/>
    <child link="left_finger"/>
    <axis xyz="1 0 0"/>
    <limit effort="50" lower="0" upper="0.85" velocity="2"/>
    <!-- <mimic joint="drive_joint" multiplier="1" offset="0"/> -->
  </joint>
  <link name="left_inner_knuckle">
    <inertial>
      <origin rpy="0 0 0" xyz="1.86600784687907E-06 0.0220467847633621 0.0261334672830885"/>
      <mass value="0.0230125781256706"/>
      <inertia ixx="6.09490024271906E-06" ixy="6.06651326160071E-11" ixz="7.19102670500635E-11" iyy="6.01955084375188E-06" iyz="-2.75316812991721E-06" izz="5.07862004479903E-06"/>
    </inertial>
    <visual>
      <geometry>
        <mesh filename="xarm_description/meshes/gripper/xarm/left_inner_knuckle_black.glb"/>
      </geometry>
      <origin rpy="0 0 0" xyz="0 0 0"/>
      <!-- <material name="Silver"/> -->
    </visual>
    <collision>
      <geometry>
        <mesh filename="xarm_description/meshes/gripper/xarm/left_inner_knuckle_black.glb"/>
      </geometry>
      <origin rpy="0 0 0" xyz="0 0 0"/>
    </collision>
  </link>
  <joint name="left_inner_knuckle_joint" type="revolute">
    <origin rpy="0.85 0 0" xyz="0 0.02 0.074098"/>
    <parent link="xarm_gripper_base_link"/>
    <child link="left_inner_knuckle"/>
    <axis xyz="-1 0 0"/>
    <limit effort="50" lower="0" upper="0.85" velocity="2"/>
    <!-- <mimic joint="drive_joint" multiplier="1" offset="0"/> -->
  </joint>
  <link name="right_outer_knuckle">
    <inertial>
      <origin rpy="0 0 0" xyz="-3.1669E-14 -0.021559 0.015181"/>
      <mass value="0.033618"/>
      <inertia ixx="1.9111E-05" ixy="-1.8789E-17" ixz="1.0986E-17" iyy="6.6256E-06" iyz="7.3008E-06" izz="1.3185E-05"/>
    </inertial>
    <visual>
      <geometry>
        <mesh filename="xarm_description/meshes/gripper/xarm/right_outer_knuckle_black.glb"/>
      </geometry>
      <origin rpy="0 0 0" xyz="0 0 0"/>
      <!-- <material name="Silver"/> -->
    </visual>
    <collision>
      <geometry>
        <mesh filename="xarm_description/meshes/gripper/xarm/right_outer_knuckle_black.glb"/>
      </geometry>
      <origin rpy="0 0 0" xyz="0 0 0"/>
    </collision>
  </link>
  <joint name="right_outer_knuckle_joint" type="revolute">
    <origin rpy="-0.85 0 0" xyz="0 -0.035 0.059098"/>
    <parent link="xarm_gripper_base_link"/>
    <child link="right_outer_knuckle"/>
    <axis xyz="1 0 0"/>
    <limit effort="50" lower="0" upper="0.85" velocity="2"/>
    <!-- <mimic joint="drive_joint" multiplier="1" offset="0"/> -->
  </joint>
  <link name="right_finger">
    <inertial>
      <origin rpy="0 0 0" xyz="2.5618E-14 0.016413 0.029258"/>
      <mass value="0.048304"/>
      <inertia ixx="1.7493E-05" ixy="-5.0014E-19" ixz="-7.5079E-18" iyy="1.7225E-05" iyz="-4.6435E-06" izz="5.1466E-06"/>
    </inertial>
    <visual>
      <geometry>
        <mesh filename="xarm_description/meshes/soft_gripper/right_finger.obj"/>
      </geometry>
      <origin rpy="0 0 0" xyz="0 0 0"/>
      <!-- <material name="Silver"/> -->
    </visual>
    <collision>
      <geometry>
        <mesh filename="xarm_description/meshes/soft_gripper/right_finger.obj"/>
      </geometry>
      <origin rpy="0 0 0" xyz="0 0 0"/>
    </collision>
  </link>
  <joint name="right_finger_joint" type="revolute">
    <origin rpy="0.85 0 0" xyz="0 -0.035465 0.042039"/>
    <parent link="right_outer_knuckle"/>
    <child link="right_finger"/>
    <axis xyz="-1 0 0"/>
    <limit effort="50" lower="0" upper="0.85" velocity="2"/>
    <!-- <mimic joint="drive_joint" multiplier="1" offset="0"/> -->
  </joint>
  <link name="right_inner_knuckle">
    <inertial>
      <origin rpy="0 0 0" xyz="1.866E-06 -0.022047 0.026133"/>
      <mass value="0.023013"/>
      <inertia ixx="6.0949E-06" ixy="-6.0665E-11" ixz="7.191E-11" iyy="6.0197E-06" iyz="2.7531E-06" izz="5.0784E-06"/>
    </inertial>
    <visual>
      <geometry>
        <mesh filename="xarm_description/meshes/gripper/xarm/right_inner_knuckle_black.glb"/>
      </geometry>
      <origin rpy="0 0 0" xyz="0 0 0"/>
      <!-- <material name="Silver"/> -->
    </visual>
    <collision>
      <geometry>
        <mesh filename="xarm_description/meshes/gripper/xarm/right_inner_knuckle_black.glb"/>
      </geometry>
      <origin rpy="0 0 0" xyz="0 0 0"/>
    </collision>
  </link>
  <joint name="right_inner_knuckle_joint" type="revolute">
    <origin rpy="-0.85 0 0" xyz="0 -0.02 0.074098"/>
    <parent link="xarm_gripper_base_link"/>
    <child link="right_inner_knuckle"/>
    <axis xyz="1 0 0"/>
    <limit effort="50" lower="0" upper="0.85" velocity="2"/>
    <!-- <mimic joint="drive_joint" multiplier="1" offset="0"/> -->
  </joint>
  <link name="link_tcp"/>
  <joint name="joint_tcp" type="fixed">
    <origin rpy="0 0 0" xyz="0 0 0.252"/>
    <parent link="xarm_gripper_base_link"/>
    <child link="link_tcp"/>
  </joint>
  <!-- Insert at the end of xarm_device_macro.xacro -->
</robot>
